Workbook
Name Slicer_AGE_RANGE: #N/A
Name Slicer_GENDER: #N/A
Name Slicer_MONTHLY_SPEND_CATEGORY: #N/A

Sheet Form Responses 1
A1: S/N | B1: GENDER | C1: AGE RANGE | D1: LOCATION | E1: SHOPPING FREQUENCY (MONTHLY) | F1: ACTIVE SHOPPER | G1: AVERAGE SPEND MONTHLY | H1: MONTHLY SPEND CATEGORY | I1: SHOPPING PLATFORMS | J1: PREFERRED PAYMENT METHODS | K1: BUYING DECISION INFLUENCE | L1: PRODUCT BOUGHT FREQUENTLY
A2: 1 | B2: Male | C2: 26-35 | D2: Lagos | E2: 5 | F2: =IF(E2>=5,"Frequent","Occasional") -> Frequent | G2: 70000 | H2: =IF(G2<20000,"Low",IF(G2<=50000,"Medium","High")) -> High | I2: WhatsApp | J2: Cash | K2: Ads | L2: Food
A3: 2 | B3: Female | C3: 18-25 | D3: Lagos | E3: 3 | F3: =IF(E3>=5,"Frequent","Occasional") -> Occasional | G3: 300000 | H3: =IF(G3<20000,"Low",IF(G3<=50000,"Medium","High")) -> High | I3: Jumia | J3: Transfer | K3: Ads | L3: Food
A4: 3 | B4: Female | C4: 18-25 | D4: Benin | E4: 1 | F4: =IF(E4>=5,"Frequent","Occasional") -> Occasional | G4: 200000 | H4: =IF(G4<20000,"Low",IF(G4<=50000,"Medium","High")) -> High | I4: Physical Store | J4: Transfer | K4: Friends | L4: Electronics
A5: 4 | B5: Male | C5: 26-35 | D5: Lagos | E5: 1 | F5: =IF(E5>=5,"Frequent","Occasional") -> Occasional | G5: 150000 | H5: =IF(G5<20000,"Low",IF(G5<=50000,"Medium","High")) -> High | I5: Others | J5: Transfer | K5: Discounts | L5: Groceries
A6: 5 | B6: Male | C6: 18-25 | D6: Lagos | E6: 1 | F6: =IF(E6>=5,"Frequent","Occasional") -> Occasional | G6: 200000 | H6: =IF(G6<20000,"Low",IF(G6<=50000,"Medium","High")) -> High | I6: Physical Store | J6: Transfer | K6: Quality | L6: Food
A7: 6 | B7: Female | C7: 26-35 | D7: Lagos | E7: 6 | F7: =IF(E7>=5,"Frequent","Occasional") -> Frequent | G7: 100000 | H7: =IF(G7<20000,"Low",IF(G7<=50000,"Medium","High")) -> High | I7: Instagram | J7: Transfer | K7: Discounts | L7: Beauty
A8: 7 | B8: Male | C8: 26-35 | D8: Lagos | E8: 1 | F8: =IF(E8>=5,"Frequent","Occasional") -> Occasional | G8: 50000 | H8: =IF(G8<20000,"Low",IF(G8<=50000,"Medium","High")) -> Medium | I8: Physical Store | J8: Transfer | K8: Quality | L8: Food
A9: 8 | B9: Female | C9: 18-25 | D9: Lagos | E9: 9 | F9: =IF(E9>=5,"Frequent","Occasional") -> Frequent | G9: 30000 | H9: =IF(G9<20000,"Low",IF(G9<=50000,"Medium","High")) -> Medium | I9: Physical Store | J9: Transfer | K9: Discounts | L9: Food
A10: 9 | B10: Male | C10: 26-35 | D10: Lagos | E10: 3 | F10: =IF(E10>=5,"Frequent","Occasional") -> Occasional | G10: 100000 | H10: =IF(G10<20000,"Low",IF(G10<=50000,"Medium","High")) -> High | I10: Jumia | J10: Transfer | K10: Discounts | L10: Groceries
A11: 10 | B11: Male | C11: 26-35 | D11: Lagos | E11: 3 | F11: =IF(E11>=5,"Frequent","Occasional") -> Occasional | G11: 75000 | H11: =IF(G11<20000,"Low",IF(G11<=50000,"Medium","High")) -> High | I11: Physical Store | J11: Card | K11: Quality | L11: Groceries
A12: 11 | B12: Male | C12: 26-35 | D12: Lagos | E12: 5 | F12: =IF(E12>=5,"Frequent","Occasional") -> Frequent | G12: 100000 | H12: =IF(G12<20000,"Low",IF(G12<=50000,"Medium","High")) -> High | I12: Jumia | J12: Transfer | K12: Discounts | L12: Food
A13: 12 | B13: Male | C13: 26-35 | D13: Lagos | E13: 2 | F13: =IF(E13>=5,"Frequent","Occasional") -> Occasional | G13: 200000 | H13: =IF(G13<20000,"Low",IF(G13<=50000,"Medium","High")) -> High | I13: Jumia | J13: Transfer | K13: Discounts | L13: Fashion
... A108: 107 | B108: Male | C108: 26-35 | D108: Lagos | E108: 5 | F108: =IF(E108>=5,"Frequent","Occasional") -> Frequent | G108: 17000 | H108: =IF(G108<20000,"Low",IF(G108<=50000,"Medium","High")) -> Low | I108: Physical Store | J108: Card | K108: Quality | L108: Food

Sheet Analysis
A1: Gender | B1: Gender Count | D1: No. of Responders | E1: Avg Shopping Frequency | F1: Average Monthly Spending
A2: Male Shoppers | B2: =COUNTIF('Form Responses 1'!$B$2:$B$108,"Male") -> 64 | D2: 107 | E2: 3.3551402 | F2: 126710.28
A3: Female Shoppers | B3: =COUNTIF('Form Responses 1'!$B$2:$B$108,"Female") -> 43 | N3: Count of AGE RANGE | O3: Column Labels | T3: Count of MONTHLY SPEND CATEGORY | U3: Column Labels
J4: Count of AVERAGE SPEND MONTHLY | K4: Column Labels | N4: Product Category | O4: 18-25 | P4: 26-35 | Q4: 36-45 | R4: Grand Total | T4: SPEND CATEGORY | U4: Card | V4: Cash | W4: Transfer | X4: Wallet
A5: Platform | B5: Total Spending | D5: PAYMENT METHODS | E5: % OF PAYMENT METHODS | G5: INCOME CATEGORY | H5: AVERAGE MONTHLY SPEND | J5: PAYMENT METHODS | K5: Female | L5: Male | N5: Beauty | O5: 4 | P5: 5 | R5: 9 | T5: Low | U5: 1 | V5: 1 | W5: 5
A6: WhatsApp | B6: =SUMIF('Form Responses 1'!$I$2:$I$108,Analysis!A6,'Form Responses 1'!$G$2:$G$108) -> 1875000 | D6: Card | E6: 0.12149533 | G6: High | H6: 177753.62 | J6: Electronics | K6: 2 | L6: 3 | N6: Electronics | O6: 2 | P6: 3 | R6: 5 | T6: Medium | U6: 4 | V6: 1 | W6: 26
A7: Instagram | B7: =SUMIF('Form Responses 1'!$I$2:$I$108,Analysis!A7,'Form Responses 1'!$G$2:$G$108) -> 1000000 | D7: Cash | E7: 0.046728972 | G7: Medium | H7: 39193.548 | J7: Beauty | K7: 8 | L7: 1 | N7: Fashion | O7: 5 | P7: 7 | Q7: 2 | R7: 14 | T7: High | U7: 8 | V7: 3 | W7: 56 | X7: 2
A8: Jumia | B8: =SUMIF('Form Responses 1'!$I$2:$I$108,Analysis!A8,'Form Responses 1'!$G$2:$G$108) -> 1220000 | D8: Transfer | E8: 0.81308411 | G8: Low | H8: 11142.857 | J8: Fashion | K8: 8 | L8: 6 | N8: Food | O8: 21 | P8: 35 | Q8: 2 | R8: 58
A9: Physical Store | B9: =SUMIF('Form Responses 1'!$I$2:$I$108,Analysis!A9,'Form Responses 1'!$G$2:$G$108) -> 9013000 | D9: Wallet | E9: 0.018691589 | J9: Groceries | K9: 4 | L9: 17 | N9: Groceries | O9: 6 | P9: 13 | Q9: 2 | R9: 21
A10: Others | B10: =SUMIF('Form Responses 1'!$I$2:$I$108,Analysis!A10,'Form Responses 1'!$G$2:$G$108) -> 450000 | D10: Grand Total | E10: 1 | J10: Food | K10: 21 | L10: 37 | N10: Grand Total | O10: 38 | P10: 63 | Q10: 6 | R10: 107
A18: Location | B18: High Spenders
A19: Anambra | B19: =COUNTIFS('Form Responses 1'!$D$2:$D$108,Analysis!A19,'Form Responses 1'!$H$2:$H$108,"High") -> 2
A20: Bayelsa | B20: =COUNTIFS('Form Responses 1'!$D$2:$D$108,Analysis!A20,'Form Responses 1'!$H$2:$H$108,"High") -> 1
A21: Benin | B21: =COUNTIFS('Form Responses 1'!$D$2:$D$108,Analysis!A21,'Form Responses 1'!$H$2:$H$108,"High") -> 2
A22: Enugu | B22: =COUNTIFS('Form Responses 1'!$D$2:$D$108,Analysis!A22,'Form Responses 1'!$H$2:$H$108,"High") -> 0 | D22: Gender | E22: % of Total | G22: PAYMENT METHODS | H22: AVERAGE SPEND MONTHLY
A23: FCT | B23: =COUNTIFS('Form Responses 1'!$D$2:$D$108,Analysis!A23,'Form Responses 1'!$H$2:$H$108,"High") -> 1 | D23: Female | E23: 0.40186916 | G23: Jumia | H23: 110909.09 | K23: AGE RANGE | L23: Count of AGE RANGE
A24: Imo | B24: =COUNTIFS('Form Responses 1'!$D$2:$D$108,Analysis!A24,'Form Responses 1'!$H$2:$H$108,"High") -> 1 | D24: Male | E24: 0.59813084 | G24: Others | H24: 112500 | K24: 36-45 | L24: 6
A25: Kaduna | B25: =COUNTIFS('Form Responses 1'!$D$2:$D$108,Analysis!A25,'Form Responses 1'!$H$2:$H$108,"High") -> 0 | D25: Grand Total | E25: 1 | G25: Instagram | H25: 125000 | K25: 18-25 | L25: 38
A26: Kano | B26: =COUNTIFS('Form Responses 1'!$D$2:$D$108,Analysis!A26,'Form Responses 1'!$H$2:$H$108,"High") -> 2 | G26: Physical Store | H26: 128757.14 | K26: 26-35 | L26: 63
A27: Kwara | B27: =COUNTIFS('Form Responses 1'!$D$2:$D$108,Analysis!A27,'Form Responses 1'!$H$2:$H$108,"High") -> 2 | G27: WhatsApp | H27: 133928.57 | K27: Grand Total | L27: 107
A28: Lagos | B28: =COUNTIFS('Form Responses 1'!$D$2:$D$108,Analysis!A28,'Form Responses 1'!$H$2:$H$108,"High") -> 48
A29: Ogun | B29: =COUNTIFS('Form Responses 1'!$D$2:$D$108,Analysis!A29,'Form Responses 1'!$H$2:$H$108,"High") -> 6
A30: Ondo | B30: =COUNTIFS('Form Responses 1'!$D$2:$D$108,Analysis!A30,'Form Responses 1'!$H$2:$H$108,"High") -> 1
A31: Osun | B31: =COUNTIFS('Form Responses 1'!$D$2:$D$108,Analysis!A31,'Form Responses 1'!$H$2:$H$108,"High") -> 1
A32: Oyo | B32: =COUNTIFS('Form Responses 1'!$D$2:$D$108,Analysis!A32,'Form Responses 1'!$H$2:$H$108,"High") -> 2
A33: Rivers | B33: =COUNTIFS('Form Responses 1'!$D$2:$D$108,Analysis!A33,'Form Responses 1'!$H$2:$H$108,"High") -> 0
A36: Location | B36: No. of Respondents | D36: Location | E36: Count of BUYING DECISION INFLUENCE
A37: Lagos | B37: 71 | D37: Influencers | E37: 2
A38: Ogun | B38: 8 | D38: Ads | E38: 4
A39: Kwara | B39: 5 | D39: Friends | E39: 5
A40: Anambra | B40: 5 | D40: Discounts | E40: 37
A41: Oyo | B41: 4 | D41: Quality | E41: 59
A42: Osun | B42: 2
A43: Benin | B43: 2
A44: FCT | B44: 2
A45: Kano | B45: 2
A46: Enugu | B46: 1
A47: Rivers | B47: 1
A48: Bayelsa | B48: 1
A49: Kaduna | B49: 1
...

Sheet Dashboard
